Workbook

Sheet LINK
A1: MONTH LINK
A2: =HYPERLINK("#'JANUARY'!A1","JANUARY") -> JANUARY
A3: =HYPERLINK("#'FEBRUARY(OR)'!A1","FEBRUARY") -> FEBRUARY
A4: =HYPERLINK("#'MARCH'!A1","MARCH") -> MARCH
A5: =HYPERLINK("#'APRIL'!A1","APRIL") -> APRIL
A6: =HYPERLINK("#'MAY'!A1","MAY") -> MAY
A7: =HYPERLINK("#'JUNE'!A1","JUNE") -> JUNE
A8: =HYPERLINK("#'JULY'!A1","JULY") -> JULY
A9: =HYPERLINK("#'AUGUST'!A1","AUGUST") -> AUGUST
A10: =HYPERLINK("#'SEPTEMBER!A1","SEPTEMBER") -> SEPTEMBER
A11: =HYPERLINK("#'OCTOBER'!A1","OCTOBER") -> OCTOBER
A12: =HYPERLINK("#'NOVEMBER'!A1","NOVEMBER") -> NOVEMBER
A13: =HYPERLINK("#'DECEMBER'!A1","DECEMBER") -> DECEMBER

Sheet JANUARY
B2: January
AD3: TOTAL PROGRESS: | AH3: 100% Complete | AI3: =COUNTIF(C39:AG39,100%) -> 20
B4: =TODAY() -> 46037 | AD4: =COUNTIF(C24:AG36,"TRUE") -> 349 | AH4: 50% Complete | AI4: =COUNTIF(C39:AG39,">50%") -> 26
B5: 2026 | AD5: =AD4/COUNTA(C24:AG36) -> 0.86600496 | AH5: 0% Complete | AI5: =COUNTIF(C39:AG39,"0%") -> 1
B7: Weekly Progress
B8: Week1
B9: =SUM(C38:I38)/COUNTA(C24:I36) -> 0.45054945
B10: Week2
B11: =SUM(J38:P38)/COUNTA(J24:P36) -> 0.98901099
B12: Week3
B13: =SUM(Q38:W38)/COUNTA(Q24:W36) -> 1
B14: Week4
B15: =SUM(X38:AD38)/COUNTA(X24:AD36) -> 0.97802198
B16: Week5
B17: =SUM(AE38:AG38)/COUNTA(AE24:AG36) -> 0.97435897
B20: Habits | C20: ="Week" &INT((DAY(C21)-1)/7)+1 -> Week1 | J20: ="Week" &INT((DAY(J21)-1)/7)+1 -> Week2 | Q20: ="Week" &INT((DAY(Q21)-1)/7)+1 -> Week3 | X20: ="Week" &INT((DAY(X21)-1)/7)+1 -> Week4 | AE20: ="Week" &INT((DAY(AE21)-1)/7)+5 -> Week9 | AH20: Complete
C21: =Sheet2!B10 -> 46023 | D21: =C21+1 -> 46024 | E21: =D21+1 -> 46025 | F21: =E21+1 -> 46026 | G21: =F21+1 -> 46027 | H21: =G21+1 -> 46028 | I21: =H21+1 -> 46029 | J21: =I21+1 -> 46030 | K21: =J21+1 -> 46031 | ... AG21: =AF21+1 -> 46053
C22: =TEXT(Sheet2!B10,"ddd") -> Thu | D22: =TEXT(D21,"ddd") -> Fri | E22: =TEXT(E21,"ddd") -> Sat | F22: =TEXT(F21,"ddd") -> Sun | G22: =TEXT(G21,"ddd") -> Mon | H22: =TEXT(H21,"ddd") -> Tue | I22: =TEXT(I21,"ddd") -> Wed | J22: =TEXT(J21,"ddd") -> Thu | K22: =TEXT(K21,"ddd") -> Fri | ... AG22: =TEXT(AG21,"ddd") -> Sat
C23: {=_xlfn.SEQUENCE(,31)} -> 1 | D23: 2 | E23: 3 | F23: 4 | G23: 5 | H23: 6 | I23: 7 | J23: 8 | K23: 9 | L23: 10 | M23: 11 | N23: 12 | O23: 13 | P23: 14 | Q23: 15 | R23: 16 | S23: 17 | T23: 18 | U23: 19 | V23: 20 | W23: 21 | X23: 22 | Y23: 23 | Z23: 24 | AA23: 25 | AB23: 26 | AC23: 27 | AD23: 28 | AE23: 29 | AF23: 30 | AG23: 31
B24: Enter Your Habit | C24: TRUE | D24: TRUE | E24: FALSE | F24: FALSE | G24: FALSE | H24: FALSE | I24: TRUE | J24: TRUE | K24: TRUE | L24: TRUE | M24: TRUE | N24: TRUE | O24: TRUE | P24: TRUE | Q24: TRUE | R24: TRUE | S24: TRUE | T24: TRUE | U24: TRUE | V24: TRUE | W24: TRUE | X24: TRUE | Y24: TRUE | Z24: TRUE | AA24: TRUE | AB24: TRUE | AC24: TRUE | AD24: TRUE | AE24: TRUE | AF24: TRUE | AG24: TRUE | AH24: =COUNTIF(C24:AG24,"True") -> 27 | AI24: 27
B25: b | C25: FALSE | D25: FALSE | E25: FALSE | F25: FALSE | G25: FALSE | H25: FALSE | I25: FALSE | J25: TRUE | K25: TRUE | L25: TRUE | M25: TRUE | N25: TRUE | O25: TRUE | P25: TRUE | Q25: TRUE | R25: TRUE | S25: TRUE | T25: TRUE | U25: TRUE | V25: TRUE | W25: TRUE | X25: TRUE | Y25: TRUE | Z25: TRUE | AA25: TRUE | AB25: TRUE | AC25: TRUE | AD25: TRUE | AE25: TRUE | AF25: TRUE | AG25: TRUE | AH25: =COUNTIF(C25:AG25,"True") -> 24 | AI25: =COUNTIF(D25:AH25,"True") -> 24
B26: c | C26: FALSE | D26: TRUE | E26: FALSE | F26: TRUE | G26: FALSE | H26: FALSE | I26: TRUE | J26: FALSE | K26: TRUE | L26: TRUE | M26: TRUE | N26: TRUE | O26: TRUE | P26: TRUE | Q26: TRUE | R26: TRUE | S26: TRUE | T26: TRUE | U26: TRUE | V26: TRUE | W26: TRUE | X26: TRUE | Y26: TRUE | Z26: TRUE | AA26: TRUE | AB26: TRUE | AC26: TRUE | AD26: TRUE | AE26: TRUE | AF26: TRUE | AG26: TRUE | AH26: =COUNTIF(C26:AG26,"True") -> 26 | AI26: =COUNTIF(D26:AH26,"True") -> 26
B27: d | C27: FALSE | D27: TRUE | E27: TRUE | F27: TRUE | G27: TRUE | H27: TRUE | I27: TRUE | J27: TRUE | K27: TRUE | L27: TRUE | M27: TRUE | N27: TRUE | O27: TRUE | P27: TRUE | Q27: TRUE | R27: TRUE | S27: TRUE | T27: TRUE | U27: TRUE | V27: TRUE | W27: TRUE | X27: TRUE | Y27: TRUE | Z27: TRUE | AA27: TRUE | AB27: TRUE | AC27: TRUE | AD27: TRUE | AE27: TRUE | AF27: TRUE | AG27: TRUE | AH27: =COUNTIF(C27:AG27,"True") -> 30 | AI27: =COUNTIF(D27:AH27,"True") -> 30
B28: e | C28: FALSE | D28: TRUE | E28: FALSE | F28: TRUE | G28: TRUE | H28: FALSE | I28: TRUE | J28: TRUE | K28: TRUE | L28: TRUE | M28: TRUE | N28: TRUE | O28: TRUE | P28: TRUE | Q28: TRUE | R28: TRUE | S28: TRUE | T28: TRUE | U28: TRUE | V28: TRUE | W28: TRUE | X28: TRUE | Y28: TRUE | Z28: TRUE | AA28: TRUE | AB28: TRUE | AC28: TRUE | AD28: TRUE | AE28: TRUE | AF28: TRUE | AG28: TRUE | AH28: =COUNTIF(C28:AG28,"True") -> 28 | AI28: =COUNTIF(D28:AH28,"True") -> 28
B29: f | C29: FALSE | D29: TRUE | E29: TRUE | F29: FALSE | G29: FALSE | H29: TRUE | I29: TRUE | J29: TRUE | K29: TRUE | L29: TRUE | M29: TRUE | N29: TRUE | O29: TRUE | P29: TRUE | Q29: TRUE | R29: TRUE | S29: TRUE | T29: TRUE | U29: TRUE | V29: TRUE | W29: TRUE | X29: TRUE | Y29: FALSE | Z29: TRUE | AA29: TRUE | AB29: TRUE | AC29: TRUE | AD29: TRUE | AE29: TRUE | AF29: TRUE | AG29: TRUE | AH29: =COUNTIF(C29:AG29,"True") -> 27 | AI29: =COUNTIF(D29:AH29,"True") -> 27
B30: g | C30: FALSE | D30: TRUE | E30: FALSE | F30: FALSE | G30: TRUE | H30: FALSE | I30: TRUE | J30: TRUE | K30: TRUE | L30: TRUE | M30: TRUE | N30: TRUE | O30: TRUE | P30: TRUE | Q30: TRUE | R30: TRUE | S30: TRUE | T30: TRUE | U30: TRUE | V30: TRUE | W30: TRUE | X30: TRUE | Y30: TRUE | Z30: TRUE | AA30: TRUE | AB30: TRUE | AC30: TRUE | AD30: TRUE | AE30: TRUE | AF30: TRUE | AG30: TRUE | AH30: =COUNTIF(C30:AG30,"True") -> 27 | AI30: =COUNTIF(D30:AH30,"True") -> 27
B31: hh | C31: FALSE | D31: TRUE | E31: TRUE | F31: TRUE | G31: FALSE | H31: TRUE | I31: TRUE | J31: TRUE | K31: TRUE | L31: TRUE | M31: TRUE | N31: TRUE | O31: TRUE | P31: TRUE | Q31: TRUE | R31: TRUE | S31: TRUE | T31: TRUE | U31: TRUE | V31: TRUE | W31: TRUE | X31: TRUE | Y31: TRUE | Z31: TRUE | AA31: FALSE | AB31: TRUE | AC31: TRUE | AD31: TRUE | AE31: TRUE | AF31: FALSE | AG31: TRUE | AH31: =COUNTIF(C31:AG31,"True") -> 27 | AI31: =COUNTIF(D31:AH31,"True") -> 27
B32: i | C32: FALSE | D32: TRUE | E32: TRUE | F32: FALSE | G32: TRUE | H32: FALSE | I32: TRUE | J32: TRUE | K32: TRUE | L32: TRUE | M32: TRUE | N32: TRUE | O32: TRUE | P32: TRUE | Q32: TRUE | R32: TRUE | S32: TRUE | T32: TRUE | U32: TRUE | V32: TRUE | W32: TRUE | X32: TRUE | Y32: TRUE | Z32: TRUE | AA32: TRUE | AB32: TRUE | AC32: TRUE | AD32: TRUE | AE32: TRUE | AF32: TRUE | AG32: TRUE | AH32: =COUNTIF(C32:AG32,"True") -> 28 | AI32: =COUNTIF(D32:AH32,"True") -> 28
B33: j | C33: FALSE | D33: FALSE | E33: TRUE | F33: FALSE | G33: FALSE | H33: TRUE | I33: TRUE | J33: TRUE | K33: TRUE | L33: TRUE | M33: TRUE | N33: TRUE | O33: TRUE | P33: TRUE | Q33: TRUE | R33: TRUE | S33: TRUE | T33: TRUE | U33: TRUE | V33: TRUE | W33: TRUE | X33: TRUE | Y33: TRUE | Z33: TRUE | AA33: TRUE | AB33: TRUE | AC33: TRUE | AD33: TRUE | AE33: TRUE | AF33: TRUE | AG33: TRUE | AH33: =COUNTIF(C33:AG33,"True") -> 27 | AI33: =COUNTIF(D33:AH33,"True") -> 27
B34: k | C34: FALSE | D34: FALSE | E34: TRUE | F34: FALSE | G34: TRUE | H34: FALSE | I34: TRUE | J34: TRUE | K34: TRUE | L34: TRUE | M34: TRUE | N34: TRUE | O34: TRUE | P34: TRUE | Q34: TRUE | R34: TRUE | S34: TRUE | T34: TRUE | U34: TRUE | V34: TRUE | W34: TRUE | X34: TRUE | Y34: TRUE | Z34: TRUE | AA34: TRUE | AB34: TRUE | AC34: TRUE | AD34: TRUE | AE34: TRUE | AF34: TRUE | AG34: TRUE | AH34: =COUNTIF(C34:AG34,"True") -> 27 | AI34: =COUNTIF(D34:AH34,"True") -> 27
B35: l | C35: FALSE | D35: FALSE | E35: FALSE | F35: FALSE | G35: TRUE | H35: FALSE | I35: TRUE | J35: TRUE | K35: TRUE | L35: TRUE | M35: TRUE | N35: TRUE | O35: TRUE | P35: TRUE | Q35: TRUE | R35: TRUE | S35: TRUE | T35: TRUE | U35: TRUE | V35: TRUE | W35: TRUE | X35: TRUE | Y35: TRUE | Z35: TRUE | AA35: TRUE | AB35: TRUE | AC35: TRUE | AD35: TRUE | AE35: TRUE | AF35: TRUE | AG35: TRUE | AH35: =COUNTIF(C35:AG35,"True") -> 26 | AI35: =COUNTIF(D35:AH35,"True") -> 26
B36: m | C36: FALSE | D36: FALSE | E36: FALSE | F36: FALSE | G36: FALSE | H36: FALSE | I36: TRUE | J36: TRUE | K36: TRUE | L36: TRUE | M36: TRUE | N36: TRUE | O36: TRUE | P36: TRUE | Q36: TRUE | R36: TRUE | S36: TRUE | T36: TRUE | U36: TRUE | V36: TRUE | W36: TRUE | X36: TRUE | Y36: TRUE | Z36: TRUE | AA36: TRUE | AB36: TRUE | AC36: TRUE | AD36: TRUE | AE36: TRUE | AF36: TRUE | AG36: TRUE | AH36: =COUNTIF(C36:AG36,"True") -> 25 | AI36: =COUNTIF(D36:AH36,"True") -> 25
B38: Task Complete | C38: =COUNTIF(C24:C36,"TRUE") -> 1 | D38: =COUNTIF(D24:D36,"TRUE") -> 8 | E38: =COUNTIF(E24:E36,"TRUE") -> 6 | F38: =COUNTIF(F24:F36,"TRUE") -> 4 | G38: =COUNTIF(G24:G36,"TRUE") -> 6 | H38: =COUNTIF(H24:H36,"TRUE") -> 4 | I38: =COUNTIF(I24:I36,"TRUE") -> 12 | J38: =COUNTIF(J24:J36,"TRUE") -> 12 | ... AG38: =COUNTIF(AG24:AG36,"TRUE") -> 13
B39: Progress % | C39: =E41 -> 0 | D39: =D38/COUNTA(D24:D36) -> 0.61538462 | E39: =E38/COUNTA(E24:E36) -> 0.46153846 | F39: =F38/COUNTA(F24:F36) -> 0.30769231 | G39: =G38/COUNTA(G24:G36) -> 0.46153846 | H39: =H38/COUNTA(H24:H36) -> 0.30769231 | I39: =I38/COUNTA(I24:I36) -> 0.92307692 | J39: =J38/COUNTA(J24:J36) -> 0.92307692 | K39: =K38/COUNTA(K24:K36) -> 1 | ... AG39: =AG38/COUNTA(AG24:AG36) -> 1
B41: Best Habit
B42: =_xlfn.XLOOKUP(MAX(AH24:AH36),AH24:AH36,B24:B36) -> d
B44: Worst Habit
B45: =_xlfn.XLOOKUP(MIN(AH24:AH36),AH24:AH36,B24:B36) -> b

Sheet FEBRUARY(OR)
B2: February
AD3: TOTAL PROGRESS: | AH3: 100% Complete | AI3: =COUNTIF(C39:AG39,100%) -> 18
B4: =TODAY() -> 46037 | AD4: =COUNTIF(C24:AG36,"TRUE") -> 343 | AH4: 50% Complete | AI4: =COUNTIF(C39:AG39,">50%") -> 27
B5: 2026 | AD5: =AD4/COUNTA(C24:AG36) -> 0.85111663 | AH5: 0% Complete | AI5: =COUNTIF(C39:AG39,"0%") -> 1
B7: Weekly Progress
B8: Week1
B9: =SUM(C38:I38)/COUNTA(C24:I36) -> 0.48351648
B10: Week2
B11: =SUM(J38:P38)/COUNTA(J24:P36) -> 0.89010989
B12: Week3
B13: =SUM(Q38:W38)/COUNTA(Q24:W36) -> 1
B14: Week4
B15: =SUM(X38:AD38)/COUNTA(X24:AD36) -> 0.97802198
B16: Week5
B17: =SUM(AE38:AG38)/COUNTA(AE24:AG36) -> 0.97435897
B20: Habits | C20: ="Week" &INT((DAY(C21)-1)/7)+1 -> Week1 | J20: ="Week" &INT((DAY(J21)-1)/7)+1 -> Week2 | Q20: ="Week" &INT((DAY(Q21)-1)/7)+1 -> Week3 | X20: ="Week" &INT((DAY(X21)-1)/7)+1 -> Week4 | AE20: ="Week" &INT((DAY(AE21)-1)/7)+5 -> Week5 | AH20: Complete
C21: =Sheet2!C6 -> 46054 | D21: =C21+1 -> 46055 | E21: =D21+1 -> 46056 | F21: =E21+1 -> 46057 | G21: =F21+1 -> 46058 | H21: =G21+1 -> 46059 | I21: =H21+1 -> 46060 | J21: =I21+1 -> 46061 | K21: =J21+1 -> 46062 | ... AG21: =AF21+1 -> 46084
C22: =TEXT(Sheet2!C6,"ddd") -> Sun | D22: =TEXT(D21,"ddd") -> Mon | E22: =TEXT(E21,"ddd") -> Tue | F22: =TEXT(F21,"ddd") -> Wed | G22: =TEXT(G21,"ddd") -> Thu | H22: =TEXT(H21,"ddd") -> Fri | I22: =TEXT(I21,"ddd") -> Sat | J22: =TEXT(J21,"ddd") -> Sun | K22: =TEXT(K21,"ddd") -> Mon | ... AG22: =TEXT(AG21,"ddd") -> Tue
C23: {=_xlfn.SEQUENCE(,31)} -> 1 | D23: 2 | E23: 3 | F23: 4 | G23: 5 | H23: 6 | I23: 7 | J23: 8 | K23: 9 | L23: 10 | M23: 11 | N23: 12 | O23: 13 | P23: 14 | Q23: 15 | R23: 16 | S23: 17 | T23: 18 | U23: 19 | V23: 20 | W23: 21 | X23: 22 | Y23: 23 | Z23: 24 | AA23: 25 | AB23: 26 | AC23: 27 | AD23: 28 | AE23: 29 | AF23: 30 | AG23: 31
B24: a | C24: TRUE | D24: TRUE | E24: FALSE | F24: FALSE | G24: FALSE | H24: FALSE | I24: TRUE | J24: TRUE | K24: TRUE | L24: TRUE | M24: TRUE | N24: TRUE | O24: TRUE | P24: TRUE | Q24: TRUE | R24: TRUE | S24: TRUE | T24: TRUE | U24: TRUE | V24: TRUE | W24: TRUE | X24: TRUE | Y24: TRUE | Z24: TRUE | AA24: TRUE | AB24: TRUE | AC24: TRUE | AD24: TRUE | AE24: TRUE | AF24: TRUE | AG24: TRUE | AH24: =COUNTIF(C24:AG24,"True") -> 27 | AI24: 27
B25: b | C25: FALSE | D25: FALSE | E25: TRUE | F25: TRUE | G25: FALSE | H25: FALSE | I25: TRUE | J25: TRUE | K25: TRUE | L25: TRUE | M25: TRUE | N25: TRUE | O25: TRUE | P25: FALSE | Q25: TRUE | R25: TRUE | S25: TRUE | T25: TRUE | U25: TRUE | V25: TRUE | W25: TRUE | X25: TRUE | Y25: TRUE | Z25: TRUE | AA25: TRUE | AB25: TRUE | AC25: TRUE | AD25: TRUE | AE25: TRUE | AF25: TRUE | AG25: TRUE | AH25: =COUNTIF(C25:AG25,"True") -> 26 | AI25: =COUNTIF(D25:AH25,"True") -> 26
B26: c | C26: FALSE | D26: TRUE | E26: FALSE | F26: TRUE | G26: FALSE | H26: FALSE | I26: TRUE | J26: FALSE | K26: TRUE | L26: TRUE | M26: TRUE | N26: TRUE | O26: TRUE | P26: FALSE | Q26: TRUE | R26: TRUE | S26: TRUE | T26: TRUE | U26: TRUE | V26: TRUE | W26: TRUE | X26: TRUE | Y26: TRUE | Z26: TRUE | AA26: TRUE | AB26: TRUE | AC26: TRUE | AD26: TRUE | AE26: TRUE | AF26: TRUE | AG26: TRUE | AH26: =COUNTIF(C26:AG26,"True") -> 25 | AI26: =COUNTIF(D26:AH26,"True") -> 25
B27: d | C27: FALSE | D27: TRUE | E27: TRUE | F27: TRUE | G27: TRUE | H27: TRUE | I27: TRUE | J27: TRUE | K27: TRUE | L27: TRUE | M27: TRUE | N27: TRUE | O27: TRUE | P27: FALSE | Q27: TRUE | R27: TRUE | S27: TRUE | T27: TRUE | U27: TRUE | V27: TRUE | W27: TRUE | X27: TRUE | Y27: TRUE | Z27: TRUE | AA27: TRUE | AB27: TRUE | AC27: TRUE | AD27: TRUE | AE27: TRUE | AF27: TRUE | AG27: TRUE | AH27: =COUNTIF(C27:AG27,"True") -> 29 | AI27: =COUNTIF(D27:AH27,"True") -> 29
B28: e | C28: FALSE | D28: TRUE | E28: FALSE | F28: TRUE | G28: TRUE | H28: FALSE | I28: TRUE | J28: TRUE | K28: TRUE | L28: TRUE | M28: TRUE | N28: FALSE | O28: FALSE | P28: FALSE | Q28: TRUE | R28: TRUE | S28: TRUE | T28: TRUE | U28: TRUE | V28: TRUE | W28: TRUE | X28: TRUE | Y28: TRUE | Z28: TRUE | AA28: TRUE | AB28: TRUE | AC28: TRUE | AD28: TRUE | AE28: TRUE | AF28: TRUE | AG28: TRUE | AH28: =COUNTIF(C28:AG28,"True") -> 25 | AI28: =COUNTIF(D28:AH28,"True") -> 25
B29: f | C29: FALSE | D29: TRUE | E29: TRUE | F29: FALSE | G29: FALSE | H29: TRUE | I29: TRUE | J29: TRUE | K29: TRUE | L29: TRUE | M29: TRUE | N29: FALSE | O29: TRUE | P29: TRUE | Q29: TRUE | R29: TRUE | S29: TRUE | T29: TRUE | U29: TRUE | V29: TRUE | W29: TRUE | X29: TRUE | Y29: FALSE | Z29: TRUE | AA29: TRUE | AB29: TRUE | AC29: TRUE | AD29: TRUE | AE29: TRUE | AF29: TRUE | AG29: TRUE | AH29: =COUNTIF(C29:AG29,"True") -> 26 | AI29: =COUNTIF(D29:AH29,"True") -> 26
B30: g | C30: FALSE | D30: TRUE | E30: FALSE | F30: FALSE | G30: TRUE | H30: FALSE | I30: TRUE | J30: TRUE | K30: TRUE | L30: TRUE | M30: TRUE | N30: TRUE | O30: TRUE | P30: TRUE | Q30: TRUE | R30: TRUE | S30: TRUE | T30: TRUE | U30: TRUE | V30: TRUE | W30: TRUE | X30: TRUE | Y30: TRUE | Z30: TRUE | AA30: TRUE | AB30: TRUE | AC30: TRUE | AD30: TRUE | AE30: TRUE | AF30: TRUE | AG30: TRUE | AH30: =COUNTIF(C30:AG30,"True") -> 27 | AI30: =COUNTIF(D30:AH30,"True") -> 27
B31: hh | C31: FALSE | D31: TRUE | E31: TRUE | F31: TRUE | G31: FALSE | H31: TRUE | I31: TRUE | J31: TRUE | K31: TRUE | L31: TRUE | M31: TRUE | N31: FALSE | O31: TRUE | P31: TRUE | Q31: TRUE | R31: TRUE | S31: TRUE | T31: TRUE | U31: TRUE | V31: TRUE | W31: TRUE | X31: TRUE | Y31: TRUE | Z31: TRUE | AA31: FALSE | AB31: TRUE | AC31: TRUE | AD31: TRUE | AE31: TRUE | AF31: FALSE | AG31: TRUE | AH31: =COUNTIF(C31:AG31,"True") -> 26 | AI31: =COUNTIF(D31:AH31,"True") -> 26
B32: i | C32: FALSE | D32: TRUE | E32: TRUE | F32: FALSE | G32: TRUE | H32: FALSE | I32: TRUE | J32: TRUE | K32: TRUE | L32: TRUE | M32: TRUE | N32: TRUE | O32: TRUE | P32: TRUE | Q32: TRUE | R32: TRUE | S32: TRUE | T32: TRUE | U32: TRUE | V32: TRUE | W32: TRUE | X32: TRUE | Y32: TRUE | Z32: TRUE | AA32: TRUE | AB32: TRUE | AC32: TRUE | AD32: TRUE | AE32: TRUE | AF32: TRUE | AG32: TRUE | AH32: =COUNTIF(C32:AG32,"True") -> 28 | AI32: =COUNTIF(D32:AH32,"True") -> 28
B33: j | C33: FALSE | D33: FALSE | E33: TRUE | F33: FALSE | G33: FALSE | H33: TRUE | I33: TRUE | J33: TRUE | K33: TRUE | L33: TRUE | M33: TRUE | N33: TRUE | O33: TRUE | P33: TRUE | Q33: TRUE | R33: TRUE | S33: TRUE | T33: TRUE | U33: TRUE | V33: TRUE | W33: TRUE | X33: TRUE | Y33: TRUE | Z33: TRUE | AA33: TRUE | AB33: TRUE | AC33: TRUE | AD33: TRUE | AE33: TRUE | AF33: TRUE | AG33: TRUE | AH33: =COUNTIF(C33:AG33,"True") -> 27 | AI33: =COUNTIF(D33:AH33,"True") -> 27
B34: k | C34: FALSE | D34: FALSE | E34: TRUE | F34: FALSE | G34: TRUE | H34: FALSE | I34: TRUE | J34: TRUE | K34: TRUE | L34: TRUE | M34: TRUE | N34: TRUE | O34: TRUE | P34: TRUE | Q34: TRUE | R34: TRUE | S34: TRUE | T34: TRUE | U34: TRUE | V34: TRUE | W34: TRUE | X34: TRUE | Y34: TRUE | Z34: TRUE | AA34: TRUE | AB34: TRUE | AC34: TRUE | AD34: TRUE | AE34: TRUE | AF34: TRUE | AG34: TRUE | AH34: =COUNTIF(C34:AG34,"True") -> 27 | AI34: =COUNTIF(D34:AH34,"True") -> 27
B35: l | C35: FALSE | D35: FALSE | E35: FALSE | F35: FALSE | G35: TRUE | H35: FALSE | I35: TRUE | J35: TRUE | K35: TRUE | L35: TRUE | M35: TRUE | N35: TRUE | O35: TRUE | P35: TRUE | Q35: TRUE | R35: TRUE | S35: TRUE | T35: TRUE | U35: TRUE | V35: TRUE | W35: TRUE | X35: TRUE | Y35: TRUE | Z35: TRUE | AA35: TRUE | AB35: TRUE | AC35: TRUE | AD35: TRUE | AE35: TRUE | AF35: TRUE | AG35: TRUE | AH35: =COUNTIF(C35:AG35,"True") -> 26 | AI35: =COUNTIF(D35:AH35,"True") -> 26
B36: m | C36: FALSE | D36: FALSE | E36: FALSE | F36: FALSE | G36: FALSE | H36: FALSE | I36: TRUE | J36: TRUE | K36: TRUE | L36: TRUE | M36: TRUE | N36: TRUE | O36: TRUE | P36: FALSE | Q36: TRUE | R36: TRUE | S36: TRUE | T36: TRUE | U36: TRUE | V36: TRUE | W36: TRUE | X36: TRUE | Y36: TRUE | Z36: TRUE | AA36: TRUE | AB36: TRUE | AC36: TRUE | AD36: TRUE | AE36: TRUE | AF36: TRUE | AG36: TRUE | AH36: =COUNTIF(C36:AG36,"True") -> 24 | AI36: =COUNTIF(D36:AH36,"True") -> 24
B38: Task Complete | C38: =COUNTIF(C24:C36,"TRUE") -> 1 | D38: =COUNTIF(D24:D36,"TRUE") -> 8 | E38: =COUNTIF(E24:E36,"TRUE") -> 7 | F38: =COUNTIF(F24:F36,"TRUE") -> 5 | G38: =COUNTIF(G24:G36,"TRUE") -> 6 | H38: =COUNTIF(H24:H36,"TRUE") -> 4 | I38: =COUNTIF(I24:I36,"TRUE") -> 13 | J38: =COUNTIF(J24:J36,"TRUE") -> 12 | ... AG38: =COUNTIF(AG24:AG36,"TRUE") -> 13
B39: Progress % | C39: =E41 -> 0 | D39: =D38/COUNTA(D24:D36) -> 0.61538462 | E39: =E38/COUNTA(E24:E36) -> 0.53846154 | F39: =F38/COUNTA(F24:F36) -> 0.38461538 | G39: =G38/COUNTA(G24:G36) -> 0.46153846 | H39: =H38/COUNTA(H24:H36) -> 0.30769231 | I39: =I38/COUNTA(I24:I36) -> 1 | J39: =J38/COUNTA(J24:J36) -> 0.92307692 | K39: =K38/COUNTA(K24:K36) -> 1 | ... AG39: =AG38/COUNTA(AG24:AG36) -> 1
B41: Best Habit
B42: =_xlfn.XLOOKUP(MAX(AH24:AH36),AH24:AH36,B24:B36) -> d
B44: Worst Habit
B45: =_xlfn.XLOOKUP(MIN(AH24:AH36),AH24:AH36,B24:B36) -> m

Sheet MARCH
B2: March
AD3: TOTAL PROGRESS: | AH3: 100% Complete | AI3: =COUNTIF(C39:AG39,100%) -> 18
B4: =TODAY() -> 46037 | AD4: =COUNTIF(C24:AG36,"TRUE") -> 341 | AH4: 50% Complete | AI4: =COUNTIF(C39:AG39,">50%") -> 27
B5: 2026 | AD5: =AD4/COUNTA(C24:AG36) -> 0.84615385 | AH5: 0% Complete | AI5: =COUNTIF(C39:AG39,"0%") -> 1
B7: Weekly Progress
B8: Week1
B9: =SUM(C38:I38)/COUNTA(C24:I36) -> 0.48351648
B10: Week2
B11: =SUM(J38:P38)/COUNTA(J24:P36) -> 0.98901099
B12: Week3
B13: =SUM(Q38:W38)/COUNTA(Q24:W36) -> 1
B14: Week4
B15: =SUM(X38:AD38)/COUNTA(X24:AD36) -> 0.85714286
B16: Week5
B17: =SUM(AE38:AG38)/COUNTA(AE24:AG36) -> 0.97435897
B20: Habits | C20: ="Week" &INT((DAY(C21)-1)/7)+1 -> Week1 | J20: ="Week" &INT((DAY(J21)-1)/7)+1 -> Week2 | Q20: ="Week" &INT((DAY(Q21)-1)/7)+1 -> Week3 | X20: ="Week" &INT((DAY(X21)-1)/7)+1 -> Week4 | AE20: ="Week" &INT((DAY(AE21)-1)/7)+1 -> Week5 | AH20: Complete
C21: =Sheet2!B9 -> 46082 | D21: =C21+1 -> 46083 | E21: =D21+1 -> 46084 | F21: =E21+1 -> 46085 | G21: =F21+1 -> 46086 | H21: =G21+1 -> 46087 | I21: =H21+1 -> 46088 | J21: =I21+1 -> 46089 | K21: =J21+1 -> 46090 | ... AG21: =AF21+1 -> 46112
C22: =TEXT(Sheet2!B9,"ddd") -> Sun | D22: =TEXT(D21,"ddd") -> Mon | E22: =TEXT(E21,"ddd") -> Tue | F22: =TEXT(F21,"ddd") -> Wed | G22: =TEXT(G21,"ddd") -> Thu | H22: =TEXT(H21,"ddd") -> Fri | I22: =TEXT(I21,"ddd") -> Sat | J22: =TEXT(J21,"ddd") -> Sun | K22: =TEXT(K21,"ddd") -> Mon | ... AG22: =TEXT(AG21,"ddd") -> Tue
C23: {=_xlfn.SEQUENCE(,31)} -> 1 | D23: 2 | E23: 3 | F23: 4 | G23: 5 | H23: 6 | I23: 7 | J23: 8 | K23: 9 | L23: 10 | M23: 11 | N23: 12 | O23: 13 | P23: 14 | Q23: 15 | R23: 16 | S23: 17 | T23: 18 | U23: 19 | V23: 20 | W23: 21 | X23: 22 | Y23: 23 | Z23: 24 | AA23: 25 | AB23: 26 | AC23: 27 | AD23: 28 | AE23: 29 | AF23: 30 | AG23: 31
B24: a | C24: TRUE | D24: TRUE | E24: FALSE | F24: FALSE | G24: FALSE | H24: FALSE | I24: TRUE | J24: TRUE | K24: TRUE | L24: TRUE | M24: TRUE | N24: TRUE | O24: TRUE | P24: TRUE | Q24: TRUE | R24: TRUE | S24: TRUE | T24: TRUE | U24: TRUE | V24: TRUE | W24: TRUE | X24: TRUE | Y24: TRUE | Z24: TRUE | AA24: FALSE | AB24: TRUE | AC24: TRUE | AD24: TRUE | AE24: TRUE | AF24: TRUE | AG24: TRUE | AH24: =COUNTIF(C24:AG24,"True") -> 26 | AI24: 27
B25: b | C25: FALSE | D25: FALSE | E25: TRUE | F25: TRUE | G25: FALSE | H25: FALSE | I25: TRUE | J25: TRUE | K25: TRUE | L25: TRUE | M25: TRUE | N25: TRUE | O25: TRUE | P25: TRUE | Q25: TRUE | R25: TRUE | S25: TRUE | T25: TRUE | U25: TRUE | V25: TRUE | W25: TRUE | X25: TRUE | Y25: TRUE | Z25: TRUE | AA25: FALSE | AB25: FALSE | AC25: TRUE | AD25: TRUE | AE25: TRUE | AF25: TRUE | AG25: TRUE | AH25: =COUNTIF(C25:AG25,"True") -> 25 | AI25: =COUNTIF(D25:AH25,"True") -> 25
B26: c | C26: FALSE | D26: TRUE | E26: FALSE | F26: TRUE | G26: FALSE | H26: FALSE | I26: TRUE | J26: FALSE | K26: TRUE | L26: TRUE | M26: TRUE | N26: TRUE | O26: TRUE | P26: TRUE | Q26: TRUE | R26: TRUE | S26: TRUE | T26: TRUE | U26: TRUE | V26: TRUE | W26: TRUE | X26: TRUE | Y26: TRUE | Z26: TRUE | AA26: FALSE | AB26: FALSE | AC26: TRUE | AD26: FALSE | AE26: TRUE | AF26: TRUE | AG26: TRUE | AH26: =COUNTIF(C26:AG26,"True") -> 23 | AI26: =COUNTIF(D26:AH26,"True") -> 23
B27: d | C27: FALSE | D27: TRUE | E27: TRUE | F27: TRUE | G27: TRUE | H27: TRUE | I27: TRUE | J27: TRUE | K27: TRUE | L27: TRUE | M27: TRUE | N27: TRUE | O27: TRUE | P27: TRUE | Q27: TRUE | R27: TRUE | S27: TRUE | T27: TRUE | U27: TRUE | V27: TRUE | W27: TRUE | X27: TRUE | Y27: TRUE | Z27: TRUE | AA27: FALSE | AB27: FALSE | AC27: FALSE | AD27: FALSE | AE27: TRUE | AF27: TRUE | AG27: TRUE | AH27: =COUNTIF(C27:AG27,"True") -> 26 | AI27: =COUNTIF(D27:AH27,"True") -> 26
B28: e | C28: FALSE | D28: TRUE | E28: FALSE | F28: TRUE | G28: TRUE | H28: FALSE | I28: TRUE | J28: TRUE | K28: TRUE | L28: TRUE | M28: TRUE | N28: TRUE | O28: TRUE | P28: TRUE | Q28: TRUE | R28: TRUE | S28: TRUE | T28: TRUE | U28: TRUE | V28: TRUE | W28: TRUE | X28: TRUE | Y28: TRUE | Z28: TRUE | AA28: TRUE | AB28: TRUE | AC28: TRUE | AD28: FALSE | AE28: TRUE | AF28: TRUE | AG28: TRUE | AH28: =COUNTIF(C28:AG28,"True") -> 27 | AI28: =COUNTIF(D28:AH28,"True") -> 27
B29: f | C29: FALSE | D29: TRUE | E29: TRUE | F29: FALSE | G29: FALSE | H29: TRUE | I29: TRUE | J29: TRUE | K29: TRUE | L29: TRUE | M29: TRUE | N29: TRUE | O29: TRUE | P29: TRUE | Q29: TRUE | R29: TRUE | S29: TRUE | T29: TRUE | U29: TRUE | V29: TRUE | W29: TRUE | X29: TRUE | Y29: FALSE | Z29: TRUE | AA29: TRUE | AB29: TRUE | AC29: TRUE | AD29: TRUE | AE29: TRUE | AF29: TRUE | AG29: TRUE | AH29: =COUNTIF(C29:AG29,"True") -> 27 | AI29: =COUNTIF(D29:AH29,"True") -> 27
B30: g | C30: FALSE | D30: TRUE | E30: FALSE | F30: FALSE | G30: TRUE | H30: FALSE | I30: TRUE | J30: TRUE | K30: TRUE | L30: TRUE | M30: TRUE | N30: TRUE | O30: TRUE | P30: TRUE | Q30: TRUE | R30: TRUE | S30: TRUE | T30: TRUE | U30: TRUE | V30: TRUE | W30: TRUE | X30: TRUE | Y30: TRUE | Z30: TRUE | AA30: TRUE | AB30: TRUE | AC30: TRUE | AD30: TRUE | AE30: TRUE | AF30: TRUE | AG30: TRUE | AH30: =COUNTIF(C30:AG30,"True") -> 27 | AI30: =COUNTIF(D30:AH30,"True") -> 27
B31: hh | C31: FALSE | D31: TRUE | E31: TRUE | F31: TRUE | G31: FALSE | H31: TRUE | I31: TRUE | J31: TRUE | K31: TRUE | L31: TRUE | M31: TRUE | N31: TRUE | O31: TRUE | P31: TRUE | Q31: TRUE | R31: TRUE | S31: TRUE | T31: TRUE | U31: TRUE | V31: TRUE | W31: TRUE | X31: TRUE | Y31: TRUE | Z31: TRUE | AA31: FALSE | AB31: TRUE | AC31: TRUE | AD31: TRUE | AE31: TRUE | AF31: FALSE | AG31: TRUE | AH31: =COUNTIF(C31:AG31,"True") -> 27 | AI31: =COUNTIF(D31:AH31,"True") -> 27
B32: i | C32: FALSE | D32: TRUE | E32: TRUE | F32: FALSE | G32: TRUE | H32: FALSE | I32: TRUE | J32: TRUE | K32: TRUE | L32: TRUE | M32: TRUE | N32: TRUE | O32: TRUE | P32: TRUE | Q32: TRUE | R32: TRUE | S32: TRUE | T32: TRUE | U32: TRUE | V32: TRUE | W32: TRUE | X32: TRUE | Y32: TRUE | Z32: TRUE | AA32: TRUE | AB32: TRUE | AC32: TRUE | AD32: TRUE | AE32: TRUE | AF32: TRUE | AG32: TRUE | AH32: =COUNTIF(C32:AG32,"True") -> 28 | AI32: =COUNTIF(D32:AH32,"True") -> 28
B33: j | C33: FALSE | D33: FALSE | E33: TRUE | F33: FALSE | G33: FALSE | H33: TRUE | I33: TRUE | J33: TRUE | K33: TRUE | L33: TRUE | M33: TRUE | N33: TRUE | O33: TRUE | P33: TRUE | Q33: TRUE | R33: TRUE | S33: TRUE | T33: TRUE | U33: TRUE | V33: TRUE | W33: TRUE | X33: TRUE | Y33: TRUE | Z33: TRUE | AA33: TRUE | AB33: TRUE | AC33: TRUE | AD33: TRUE | AE33: TRUE | AF33: TRUE | AG33: TRUE | AH33: =COUNTIF(C33:AG33,"True") -> 27 | AI33: =COUNTIF(D33:AH33,"True") -> 27
B34: k | C34: FALSE | D34: FALSE | E34: TRUE | F34: FALSE | G34: TRUE | H34: FALSE | I34: TRUE | J34: TRUE | K34: TRUE | L34: TRUE | M34: TRUE | N34: TRUE | O34: TRUE | P34: TRUE | Q34: TRUE | R34: TRUE | S34: TRUE | T34: TRUE | U34: TRUE | V34: TRUE | W34: TRUE | X34: TRUE | Y34: TRUE | Z34: TRUE | AA34: TRUE | AB34: TRUE | AC34: TRUE | AD34: TRUE | AE34: TRUE | AF34: TRUE | AG34: TRUE | AH34: =COUNTIF(C34:AG34,"True") -> 27 | AI34: =COUNTIF(D34:AH34,"True") -> 27
B35: l | C35: FALSE | D35: FALSE | E35: FALSE | F35: FALSE | G35: TRUE | H35: FALSE | I35: TRUE | J35: TRUE | K35: TRUE | L35: TRUE | M35: TRUE | N35: TRUE | O35: TRUE | P35: TRUE | Q35: TRUE | R35: TRUE | S35: TRUE | T35: TRUE | U35: TRUE | V35: TRUE | W35: TRUE | X35: TRUE | Y35: TRUE | Z35: TRUE | AA35: TRUE | AB35: TRUE | AC35: TRUE | AD35: TRUE | AE35: TRUE | AF35: TRUE | AG35: TRUE | AH35: =COUNTIF(C35:AG35,"True") -> 26 | AI35: =COUNTIF(D35:AH35,"True") -> 26
B36: m | C36: FALSE | D36: FALSE | E36: FALSE | F36: FALSE | G36: FALSE | H36: FALSE | I36: TRUE | J36: TRUE | K36: TRUE | L36: TRUE | M36: TRUE | N36: TRUE | O36: TRUE | P36: TRUE | Q36: TRUE | R36: TRUE | S36: TRUE | T36: TRUE | U36: TRUE | V36: TRUE | W36: TRUE | X36: TRUE | Y36: TRUE | Z36: TRUE | AA36: TRUE | AB36: TRUE | AC36: TRUE | AD36: TRUE | AE36: TRUE | AF36: TRUE | AG36: TRUE | AH36: =COUNTIF(C36:AG36,"True") -> 25 | AI36: =COUNTIF(D36:AH36,"True") -> 25
B38: Task Complete | C38: =COUNTIF(C24:C36,"TRUE") -> 1 | D38: =COUNTIF(D24:D36,"TRUE") -> 8 | E38: =COUNTIF(E24:E36,"TRUE") -> 7 | F38: =COUNTIF(F24:F36,"TRUE") -> 5 | G38: =COUNTIF(G24:G36,"TRUE") -> 6 | H38: =COUNTIF(H24:H36,"TRUE") -> 4 | I38: =COUNTIF(I24:I36,"TRUE") -> 13 | J38: =COUNTIF(J24:J36,"TRUE") -> 12 | ... AG38: =COUNTIF(AG24:AG36,"TRUE") -> 13
B39: Progress % | C39: =E41 -> 0 | D39: =D38/COUNTA(D24:D36) -> 0.61538462 | E39: =E38/COUNTA(E24:E36) -> 0.53846154 | F39: =F38/COUNTA(F24:F36) -> 0.38461538 | G39: =G38/COUNTA(G24:G36) -> 0.46153846 | H39: =H38/COUNTA(H24:H36) -> 0.30769231 | I39: =I38/COUNTA(I24:I36) -> 1 | J39: =J38/COUNTA(J24:J36) -> 0.92307692 | K39: =K38/COUNTA(K24:K36) -> 1 | ... AG39: =AG38/COUNTA(AG24:AG36) -> 1
B41: Best Habit
B42: =_xlfn.XLOOKUP(MAX(AH24:AH36),AH24:AH36,B24:B36) -> i
B44: Worst Habit
B45: =_xlfn.XLOOKUP(MIN(AH24:AH36),AH24:AH36,B24:B36) -> c
S52: =Sheet2!B9 -> 46082

Sheet APRIL
B2: April
AD3: TOTAL PROGRESS: | AH3: 100% Complete | AI3: =COUNTIF(C39:AG39,100%) -> 21
B4: =TODAY() -> 46037 | AD4: =COUNTIF(C24:AG36,"TRUE") -> 352 | AH4: 50% Complete | AI4: =COUNTIF(C39:AG39,">50%") -> 27
B5: 2026 | AD5: =AD4/COUNTA(C24:AG36) -> 0.87344913 | AH5: 0% Complete | AI5: =COUNTIF(C39:AG39,"0%") -> 1
B7: Weekly Progress
B8: Week1
B9: =SUM(C38:I38)/COUNTA(C24:I36) -> 0.48351648
B10: Week2
B11: =SUM(J38:P38)/COUNTA(J24:P36) -> 0.98901099
B12: Week3
B13: =SUM(Q38:W38)/COUNTA(Q24:W36) -> 1
B14: Week4
B15: =SUM(X38:AD38)/COUNTA(X24:AD36) -> 0.97802198
B16: Week5
B17: =SUM(AE38:AG38)/COUNTA(AE24:AG36) -> 0.97435897
B20: Habits | C20: ="Week" &INT((DAY(C21)-1)/7)+1 -> Week1 | J20: ="Week" &INT((DAY(J21)-1)/7)+1 -> Week2 | Q20: ="Week" &INT((DAY(Q21)-1)/7)+1 -> Week3 | X20: ="Week" &INT((DAY(X21)-1)/7)+1 -> Week4 | AE20: ="Week" &INT((DAY(AE21)-1)/7)+1 -> Week5 | AH20: Complete
C21: =Sheet2!B11 -> 46113 | D21: =C21+1 -> 46114 | E21: =D21+1 -> 46115 | F21: =E21+1 -> 46116 | G21: =F21+1 -> 46117 | H21: =G21+1 -> 46118 | I21: =H21+1 -> 46119 | J21: =I21+1 -> 46120 | K21: =J21+1 -> 46121 | ... AG21: =AF21+1 -> 46143
C22: =TEXT(Sheet2!B11,"ddd") -> Wed | D22: =TEXT(D21,"ddd") -> Thu | E22: =TEXT(E21,"ddd") -> Fri | F22: =TEXT(F21,"ddd") -> Sat | G22: =TEXT(G21,"ddd") -> Sun | H22: =TEXT(H21,"ddd") -> Mon | I22: =TEXT(I21,"ddd") -> Tue | J22: =TEXT(J21,"ddd") -> Wed | K22: =TEXT(K21,"ddd") -> Thu | ... AG22: =TEXT(AG21,"ddd") -> Fri
C23: {=_xlfn.SEQUENCE(,31)} -> 1 | D23: 2 | E23: 3 | F23: 4 | G23: 5 | H23: 6 | I23: 7 | J23: 8 | K23: 9 | L23: 10 | M23: 11 | N23: 12 | O23: 13 | P23: 14 | Q23: 15 | R23: 16 | S23: 17 | T23: 18 | U23: 19 | V23: 20 | W23: 21 | X23: 22 | Y23: 23 | Z23: 24 | AA23: 25 | AB23: 26 | AC23: 27 | AD23: 28 | AE23: 29 | AF23: 30 | AG23: 31
B24: a | C24: TRUE | D24: TRUE | E24: FALSE | F24: FALSE | G24: FALSE | H24: FALSE | I24: TRUE | J24: TRUE | K24: TRUE | L24: TRUE | M24: TRUE | N24: TRUE | O24: TRUE | P24: TRUE | Q24: TRUE | R24: TRUE | S24: TRUE | T24: TRUE | U24: TRUE | V24: TRUE | W24: TRUE | X24: TRUE | Y24: TRUE | Z24: TRUE | AA24: TRUE | AB24: TRUE | AC24: TRUE | AD24: TRUE | AE24: TRUE | AF24: TRUE | AG24: TRUE | AH24: =COUNTIF(C24:AG24,"True") -> 27 | AI24: 27
B25: b | C25: FALSE | D25: FALSE | E25: TRUE | F25: TRUE | G25: FALSE | H25: FALSE | I25: TRUE | J25: TRUE | K25: TRUE | L25: TRUE | M25: TRUE | N25: TRUE | O25: TRUE | P25: TRUE | Q25: TRUE | R25: TRUE | S25: TRUE | T25: TRUE | U25: TRUE | V25: TRUE | W25: TRUE | X25: TRUE | Y25: TRUE | Z25: TRUE | AA25: TRUE | AB25: TRUE | AC25: TRUE | AD25: TRUE | AE25: TRUE | AF25: TRUE | AG25: TRUE | AH25: =COUNTIF(C25:AG25,"True") -> 27 | AI25: =COUNTIF(D25:AH25,"True") -> 27
B26: c | C26: FALSE | D26: TRUE | E26: FALSE | F26: TRUE | G26: FALSE | H26: FALSE | I26: TRUE | J26: FALSE | K26: TRUE | L26: TRUE | M26: TRUE | N26: TRUE | O26: TRUE | P26: TRUE | Q26: TRUE | R26: TRUE | S26: TRUE | T26: TRUE | U26: TRUE | V26: TRUE | W26: TRUE | X26: TRUE | Y26: TRUE | Z26: TRUE | AA26: TRUE | AB26: TRUE | AC26: TRUE | AD26: TRUE | AE26: TRUE | AF26: TRUE | AG26: TRUE | AH26: =COUNTIF(C26:AG26,"True") -> 26 | AI26: =COUNTIF(D26:AH26,"True") -> 26
B27: d | C27: FALSE | D27: TRUE | E27: TRUE | F27: TRUE | G27: TRUE | H27: TRUE | I27: TRUE | J27: TRUE | K27: TRUE | L27: TRUE | M27: TRUE | N27: TRUE | O27: TRUE | P27: TRUE | Q27: TRUE | R27: TRUE | S27: TRUE | T27: TRUE | U27: TRUE | V27: TRUE | W27: TRUE | X27: TRUE | Y27: TRUE | Z27: TRUE | AA27: TRUE | AB27: TRUE | AC27: TRUE | AD27: TRUE | AE27: TRUE | AF27: TRUE | AG27: TRUE | AH27: =COUNTIF(C27:AG27,"True") -> 30 | AI27: =COUNTIF(D27:AH27,"True") -> 30
B28: e | C28: FALSE | D28: TRUE | E28: FALSE | F28: TRUE | G28: TRUE | H28: FALSE | I28: TRUE | J28: TRUE | K28: TRUE | L28: TRUE | M28: TRUE | N28: TRUE | O28: TRUE | P28: TRUE | Q28: TRUE | R28: TRUE | S28: TRUE | T28: TRUE | U28: TRUE | V28: TRUE | W28: TRUE | X28: TRUE | Y28: TRUE | Z28: TRUE | AA28: TRUE | AB28: TRUE | AC28: TRUE | AD28: TRUE | AE28: TRUE | AF28: TRUE | AG28: TRUE | AH28: =COUNTIF(C28:AG28,"True") -> 28 | AI28: =COUNTIF(D28:AH28,"True") -> 28
B29: f | C29: FALSE | D29: TRUE | E29: TRUE | F29: FALSE | G29: FALSE | H29: TRUE | I29: TRUE | J29: TRUE | K29: TRUE | L29: TRUE | M29: TRUE | N29: TRUE | O29: TRUE | P29: TRUE | Q29: TRUE | R29: TRUE | S29: TRUE | T29: TRUE | U29: TRUE | V29: TRUE | W29: TRUE | X29: TRUE | Y29: FALSE | Z29: TRUE | AA29: TRUE | AB29: TRUE | AC29: TRUE | AD29: TRUE | AE29: TRUE | AF29: TRUE | AG29: TRUE | AH29: =COUNTIF(C29:AG29,"True") -> 27 | AI29: =COUNTIF(D29:AH29,"True") -> 27
B30: g | C30: FALSE | D30: TRUE | E30: FALSE | F30: FALSE | G30: TRUE | H30: FALSE | I30: TRUE | J30: TRUE | K30: TRUE | L30: TRUE | M30: TRUE | N30: TRUE | O30: TRUE | P30: TRUE | Q30: TRUE | R30: TRUE | S30: TRUE | T30: TRUE | U30: TRUE | V30: TRUE | W30: TRUE | X30: TRUE | Y30: TRUE | Z30: TRUE | AA30: TRUE | AB30: TRUE | AC30: TRUE | AD30: TRUE | AE30: TRUE | AF30: TRUE | AG30: TRUE | AH30: =COUNTIF(C30:AG30,"True") -> 27 | AI30: =COUNTIF(D30:AH30,"True") -> 27
B31: hh | C31: FALSE | D31: TRUE | E31: TRUE | F31: TRUE | G31: FALSE | H31: TRUE | I31: TRUE | J31: TRUE | K31: TRUE | L31: TRUE | M31: TRUE | N31: TRUE | O31: TRUE | P31: TRUE | Q31: TRUE | R31: TRUE | S31: TRUE | T31: TRUE | U31: TRUE | V31: TRUE | W31: TRUE | X31: TRUE | Y31: TRUE | Z31: TRUE | AA31: FALSE | AB31: TRUE | AC31: TRUE | AD31: TRUE | AE31: TRUE | AF31: FALSE | AG31: TRUE | AH31: =COUNTIF(C31:AG31,"True") -> 27 | AI31: =COUNTIF(D31:AH31,"True") -> 27
B32: i | C32: FALSE | D32: TRUE | E32: TRUE | F32: FALSE | G32: TRUE | H32: FALSE | I32: TRUE | J32: TRUE | K32: TRUE | L32: TRUE | M32: TRUE | N32: TRUE | O32: TRUE | P32: TRUE | Q32: TRUE | R32: TRUE | S32: TRUE | T32: TRUE | U32: TRUE | V32: TRUE | W32: TRUE | X32: TRUE | Y32: TRUE | Z32: TRUE | AA32: TRUE | AB32: TRUE | AC32: TRUE | AD32: TRUE | AE32: TRUE | AF32: TRUE | AG32: TRUE | AH32: =COUNTIF(C32:AG32,"True") -> 28 | AI32: =COUNTIF(D32:AH32,"True") -> 28
B33: j | C33: FALSE | D33: FALSE | E33: TRUE | F33: FALSE | G33: FALSE | H33: TRUE | I33: TRUE | J33: TRUE | K33: TRUE | L33: TRUE | M33: TRUE | N33: TRUE | O33: TRUE | P33: TRUE | Q33: TRUE | R33: TRUE | S33: TRUE | T33: TRUE | U33: TRUE | V33: TRUE | W33: TRUE | X33: TRUE | Y33: TRUE | Z33: TRUE | AA33: TRUE | AB33: TRUE | AC33: TRUE | AD33: TRUE | AE33: TRUE | AF33: TRUE | AG33: TRUE | AH33: =COUNTIF(C33:AG33,"True") -> 27 | AI33: =COUNTIF(D33:AH33,"True") -> 27
B34: k | C34: FALSE | D34: FALSE | E34: TRUE | F34: FALSE | G34: TRUE | H34: FALSE | I34: TRUE | J34: TRUE | K34: TRUE | L34: TRUE | M34: TRUE | N34: TRUE | O34: TRUE | P34: TRUE | Q34: TRUE | R34: TRUE | S34: TRUE | T34: TRUE | U34: TRUE | V34: TRUE | W34: TRUE | X34: TRUE | Y34: TRUE | Z34: TRUE | AA34: TRUE | AB34: TRUE | AC34: TRUE | AD34: TRUE | AE34: TRUE | AF34: TRUE | AG34: TRUE | AH34: =COUNTIF(C34:AG34,"True") -> 27 | AI34: =COUNTIF(D34:AH34,"True") -> 27
B35: l | C35: FALSE | D35: FALSE | E35: FALSE | F35: FALSE | G35: TRUE | H35: FALSE | I35: TRUE | J35: TRUE | K35: TRUE | L35: TRUE | M35: TRUE | N35: TRUE | O35: TRUE | P35: TRUE | Q35: TRUE | R35: TRUE | S35: TRUE | T35: TRUE | U35: TRUE | V35: TRUE | W35: TRUE | X35: TRUE | Y35: TRUE | Z35: TRUE | AA35: TRUE | AB35: TRUE | AC35: TRUE | AD35: TRUE | AE35: TRUE | AF35: TRUE | AG35: TRUE | AH35: =COUNTIF(C35:AG35,"True") -> 26 | AI35: =COUNTIF(D35:AH35,"True") -> 26
B36: m | C36: FALSE | D36: FALSE | E36: FALSE | F36: FALSE | G36: FALSE | H36: FALSE | I36: TRUE | J36: TRUE | K36: TRUE | L36: TRUE | M36: TRUE | N36: TRUE | O36: TRUE | P36: TRUE | Q36: TRUE | R36: TRUE | S36: TRUE | T36: TRUE | U36: TRUE | V36: TRUE | W36: TRUE | X36: TRUE | Y36: TRUE | Z36: TRUE | AA36: TRUE | AB36: TRUE | AC36: TRUE | AD36: TRUE | AE36: TRUE | AF36: TRUE | AG36: TRUE | AH36: =COUNTIF(C36:AG36,"True") -> 25 | AI36: =COUNTIF(D36:AH36,"True") -> 25
B38: Task Complete | C38: =COUNTIF(C24:C36,"TRUE") -> 1 | D38: =COUNTIF(D24:D36,"TRUE") -> 8 | E38: =COUNTIF(E24:E36,"TRUE") -> 7 | F38: =COUNTIF(F24:F36,"TRUE") -> 5 | G38: =COUNTIF(G24:G36,"TRUE") -> 6 | H38: =COUNTIF(H24:H36,"TRUE") -> 4 | I38: =COUNTIF(I24:I36,"TRUE") -> 13 | J38: =COUNTIF(J24:J36,"TRUE") -> 12 | ... AG38: =COUNTIF(AG24:AG36,"TRUE") -> 13
B39: Progress % | C39: =E41 -> 0 | D39: =D38/COUNTA(D24:D36) -> 0.61538462 | E39: =E38/COUNTA(E24:E36) -> 0.53846154 | F39: =F38/COUNTA(F24:F36) -> 0.38461538 | G39: =G38/COUNTA(G24:G36) -> 0.46153846 | H39: =H38/COUNTA(H24:H36) -> 0.30769231 | I39: =I38/COUNTA(I24:I36) -> 1 | J39: =J38/COUNTA(J24:J36) -> 0.92307692 | K39: =K38/COUNTA(K24:K36) -> 1 | ... AG39: =AG38/COUNTA(AG24:AG36) -> 1
B41: Best Habit
B42: =_xlfn.XLOOKUP(MAX(AH24:AH36),AH24:AH36,B24:B36) -> d
B44: Worst Habit
B45: =_xlfn.XLOOKUP(MIN(AH24:AH36),AH24:AH36,B24:B36) -> m

Sheet MAY
B2: May
AD3: TOTAL PROGRESS: | AH3: 100% Complete | AI3: =COUNTIF(C39:AG39,100%) -> 21
B4: =TODAY() -> 46037 | AD4: =COUNTIF(C24:AG36,"TRUE") -> 352 | AH4: 50% Complete | AI4: =COUNTIF(C39:AG39,">50%") -> 27
B5: 2026 | AD5: =AD4/COUNTA(C24:AG36) -> 0.87344913 | AH5: 0% Complete | AI5: =COUNTIF(C39:AG39,"0%") -> 1
B7: Weekly Progress
B8: Week1
B9: =SUM(C38:I38)/COUNTA(C24:I36) -> 0.48351648
B10: Week2
B11: =SUM(J38:P38)/COUNTA(J24:P36) -> 0.98901099
B12: Week3
B13: =SUM(Q38:W38)/COUNTA(Q24:W36) -> 1
B14: Week4
B15: =SUM(X38:AD38)/COUNTA(X24:AD36) -> 0.97802198
B16: Week5
B17: =SUM(AE38:AG38)/COUNTA(AE24:AG36) -> 0.97435897
B20: Habits | C20: ="Week" &INT((DAY(C21)-1)/7)+1 -> Week1 | J20: ="Week" &INT((DAY(J21)-1)/7)+1 -> Week2 | Q20: ="Week" &INT((DAY(Q21)-1)/7)+1 -> Week3 | X20: ="Week" &INT((DAY(X21)-1)/7)+1 -> Week4 | AE20: ="Week" &INT((DAY(AE21)-1)/7)+1 -> Week5 | AH20: Complete
C21: =Sheet2!B12 -> 46143 | D21: =C21+1 -> 46144 | E21: =D21+1 -> 46145 | F21: =E21+1 -> 46146 | G21: =F21+1 -> 46147 | H21: =G21+1 -> 46148 | I21: =H21+1 -> 46149 | J21: =I21+1 -> 46150 | K21: =J21+1 -> 46151 | ... AG21: =AF21+1 -> 46173
C22: =TEXT(Sheet2!B12,"ddd") -> Fri | D22: =TEXT(D21,"ddd") -> Sat | E22: =TEXT(E21,"ddd") -> Sun | F22: =TEXT(F21,"ddd") -> Mon | G22: =TEXT(G21,"ddd") -> Tue | H22: =TEXT(H21,"ddd") -> Wed | I22: =TEXT(I21,"ddd") -> Thu | J22: =TEXT(J21,"ddd") -> Fri | K22: =TEXT(K21,"ddd") -> Sat | ... AG22: =TEXT(AG21,"ddd") -> Sun
C23: {=_xlfn.SEQUENCE(,31)} -> 1 | D23: 2 | E23: 3 | F23: 4 | G23: 5 | H23: 6 | I23: 7 | J23: 8 | K23: 9 | L23: 10 | M23: 11 | N23: 12 | O23: 13 | P23: 14 | Q23: 15 | R23: 16 | S23: 17 | T23: 18 | U23: 19 | V23: 20 | W23: 21 | X23: 22 | Y23: 23 | Z23: 24 | AA23: 25 | AB23: 26 | AC23: 27 | AD23: 28 | AE23: 29 | AF23: 30 | AG23: 31
B24: a | C24: TRUE | D24: TRUE | E24: FALSE | F24: FALSE | G24: FALSE | H24: FALSE | I24: TRUE | J24: TRUE | K24: TRUE | L24: TRUE | M24: TRUE | N24: TRUE | O24: TRUE | P24: TRUE | Q24: TRUE | R24: TRUE | S24: TRUE | T24: TRUE | U24: TRUE | V24: TRUE | W24: TRUE | X24: TRUE | Y24: TRUE | Z24: TRUE | AA24: TRUE | AB24: TRUE | AC24: TRUE | AD24: TRUE | AE24: TRUE | AF24: TRUE | AG24: TRUE | AH24: =COUNTIF(C24:AG24,"True") -> 27 | AI24: 27
B25: b | C25: FALSE | D25: FALSE | E25: TRUE | F25: TRUE | G25: FALSE | H25: FALSE | I25: TRUE | J25: TRUE | K25: TRUE | L25: TRUE | M25: TRUE | N25: TRUE | O25: TRUE | P25: TRUE | Q25: TRUE | R25: TRUE | S25: TRUE | T25: TRUE | U25: TRUE | V25: TRUE | W25: TRUE | X25: TRUE | Y25: TRUE | Z25: TRUE | AA25: TRUE | AB25: TRUE | AC25: TRUE | AD25: TRUE | AE25: TRUE | AF25: TRUE | AG25: TRUE | AH25: =COUNTIF(C25:AG25,"True") -> 27 | AI25: =COUNTIF(D25:AH25,"True") -> 27
B26: c | C26: FALSE | D26: TRUE | E26: FALSE | F26: TRUE | G26: FALSE | H26: FALSE | I26: TRUE | J26: FALSE | K26: TRUE | L26: TRUE | M26: TRUE | N26: TRUE | O26: TRUE | P26: TRUE | Q26: TRUE | R26: TRUE | S26: TRUE | T26: TRUE | U26: TRUE | V26: TRUE | W26: TRUE | X26: TRUE | Y26: TRUE | Z26: TRUE | AA26: TRUE | AB26: TRUE | AC26: TRUE | AD26: TRUE | AE26: TRUE | AF26: TRUE | AG26: TRUE | AH26: =COUNTIF(C26:AG26,"True") -> 26 | AI26: =COUNTIF(D26:AH26,"True") -> 26
B27: d | C27: FALSE | D27: TRUE | E27: TRUE | F27: TRUE | G27: TRUE | H27: TRUE | I27: TRUE | J27: TRUE | K27: TRUE | L27: TRUE | M27: TRUE | N27: TRUE | O27: TRUE | P27: TRUE | Q27: TRUE | R27: TRUE | S27: TRUE | T27: TRUE | U27: TRUE | V27: TRUE | W27: TRUE | X27: TRUE | Y27: TRUE | Z27: TRUE | AA27: TRUE | AB27: TRUE | AC27: TRUE | AD27: TRUE | AE27: TRUE | AF27: TRUE | AG27: TRUE | AH27: =COUNTIF(C27:AG27,"True") -> 30 | AI27: =COUNTIF(D27:AH27,"True") -> 30
B28: e | C28: FALSE | D28: TRUE | E28: FALSE | F28: TRUE | G28: TRUE | H28: FALSE | I28: TRUE | J28: TRUE | K28: TRUE | L28: TRUE | M28: TRUE | N28: TRUE | O28: TRUE | P28: TRUE | Q28: TRUE | R28: TRUE | S28: TRUE | T28: TRUE | U28: TRUE | V28: TRUE | W28: TRUE | X28: TRUE | Y28: TRUE | Z28: TRUE | AA28: TRUE | AB28: TRUE | AC28: TRUE | AD28: TRUE | AE28: TRUE | AF28: TRUE | AG28: TRUE | AH28: =COUNTIF(C28:AG28,"True") -> 28 | AI28: =COUNTIF(D28:AH28,"True") -> 28
B29: f | C29: FALSE | D29: TRUE | E29: TRUE | F29: FALSE | G29: FALSE | H29: TRUE | I29: TRUE | J29: TRUE | K29: TRUE | L29: TRUE | M29: TRUE | N29: TRUE | O29: TRUE | P29: TRUE | Q29: TRUE | R29: TRUE | S29: TRUE | T29: TRUE | U29: TRUE | V29: TRUE | W29: TRUE | X29: TRUE | Y29: FALSE | Z29: TRUE | AA29: TRUE | AB29: TRUE | AC29: TRUE | AD29: TRUE | AE29: TRUE | AF29: TRUE | AG29: TRUE | AH29: =COUNTIF(C29:AG29,"True") -> 27 | AI29: =COUNTIF(D29:AH29,"True") -> 27
B30: g | C30: FALSE | D30: TRUE | E30: FALSE | F30: FALSE | G30: TRUE | H30: FALSE | I30: TRUE | J30: TRUE | K30: TRUE | L30: TRUE | M30: TRUE | N30: TRUE | O30: TRUE | P30: TRUE | Q30: TRUE | R30: TRUE | S30: TRUE | T30: TRUE | U30: TRUE | V30: TRUE | W30: TRUE | X30: TRUE | Y30: TRUE | Z30: TRUE | AA30: TRUE | AB30: TRUE | AC30: TRUE | AD30: TRUE | AE30: TRUE | AF30: TRUE | AG30: TRUE | AH30: =COUNTIF(C30:AG30,"True") -> 27 | AI30: =COUNTIF(D30:AH30,"True") -> 27
B31: hh | C31: FALSE | D31: TRUE | E31: TRUE | F31: TRUE | G31: FALSE | H31: TRUE | I31: TRUE | J31: TRUE | K31: TRUE | L31: TRUE | M31: TRUE | N31: TRUE | O31: TRUE | P31: TRUE | Q31: TRUE | R31: TRUE | S31: TRUE | T31: TRUE | U31: TRUE | V31: TRUE | W31: TRUE | X31: TRUE | Y31: TRUE | Z31: TRUE | AA31: FALSE | AB31: TRUE | AC31: TRUE | AD31: TRUE | AE31: TRUE | AF31: FALSE | AG31: TRUE | AH31: =COUNTIF(C31:AG31,"True") -> 27 | AI31: =COUNTIF(D31:AH31,"True") -> 27
B32: i | C32: FALSE | D32: TRUE | E32: TRUE | F32: FALSE | G32: TRUE | H32: FALSE | I32: TRUE | J32: TRUE | K32: TRUE | L32: TRUE | M32: TRUE | N32: TRUE | O32: TRUE | P32: TRUE | Q32: TRUE | R32: TRUE | S32: TRUE | T32: TRUE | U32: TRUE | V32: TRUE | W32: TRUE | X32: TRUE | Y32: TRUE | Z32: TRUE | AA32: TRUE | AB32: TRUE | AC32: TRUE | AD32: TRUE | AE32: TRUE | AF32: TRUE | AG32: TRUE | AH32: =COUNTIF(C32:AG32,"True") -> 28 | AI32: =COUNTIF(D32:AH32,"True") -> 28
B33: j | C33: FALSE | D33: FALSE | E33: TRUE | F33: FALSE | G33: FALSE | H33: TRUE | I33: TRUE | J33: TRUE | K33: TRUE | L33: TRUE | M33: TRUE | N33: TRUE | O33: TRUE | P33: TRUE | Q33: TRUE | R33: TRUE | S33: TRUE | T33: TRUE | U33: TRUE | V33: TRUE | W33: TRUE | X33: TRUE | Y33: TRUE | Z33: TRUE | AA33: TRUE | AB33: TRUE | AC33: TRUE | AD33: TRUE | AE33: TRUE | AF33: TRUE | AG33: TRUE | AH33: =COUNTIF(C33:AG33,"True") -> 27 | AI33: =COUNTIF(D33:AH33,"True") -> 27
B34: k | C34: FALSE | D34: FALSE | E34: TRUE | F34: FALSE | G34: TRUE | H34: FALSE | I34: TRUE | J34: TRUE | K34: TRUE | L34: TRUE | M34: TRUE | N34: TRUE | O34: TRUE | P34: TRUE | Q34: TRUE | R34: TRUE | S34: TRUE | T34: TRUE | U34: TRUE | V34: TRUE | W34: TRUE | X34: TRUE | Y34: TRUE | Z34: TRUE | AA34: TRUE | AB34: TRUE | AC34: TRUE | AD34: TRUE | AE34: TRUE | AF34: TRUE | AG34: TRUE | AH34: =COUNTIF(C34:AG34,"True") -> 27 | AI34: =COUNTIF(D34:AH34,"True") -> 27
B35: l | C35: FALSE | D35: FALSE | E35: FALSE | F35: FALSE | G35: TRUE | H35: FALSE | I35: TRUE | J35: TRUE | K35: TRUE | L35: TRUE | M35: TRUE | N35: TRUE | O35: TRUE | P35: TRUE | Q35: TRUE | R35: TRUE | S35: TRUE | T35: TRUE | U35: TRUE | V35: TRUE | W35: TRUE | X35: TRUE | Y35: TRUE | Z35: TRUE | AA35: TRUE | AB35: TRUE | AC35: TRUE | AD35: TRUE | AE35: TRUE | AF35: TRUE | AG35: TRUE | AH35: =COUNTIF(C35:AG35,"True") -> 26 | AI35: =COUNTIF(D35:AH35,"True") -> 26
B36: m | C36: FALSE | D36: FALSE | E36: FALSE | F36: FALSE | G36: FALSE | H36: FALSE | I36: TRUE | J36: TRUE | K36: TRUE | L36: TRUE | M36: TRUE | N36: TRUE | O36: TRUE | P36: TRUE | Q36: TRUE | R36: TRUE | S36: TRUE | T36: TRUE | U36: TRUE | V36: TRUE | W36: TRUE | X36: TRUE | Y36: TRUE | Z36: TRUE | AA36: TRUE | AB36: TRUE | AC36: TRUE | AD36: TRUE | AE36: TRUE | AF36: TRUE | AG36: TRUE | AH36: =COUNTIF(C36:AG36,"True") -> 25 | AI36: =COUNTIF(D36:AH36,"True") -> 25
B38: Task Complete | C38: =COUNTIF(C24:C36,"TRUE") -> 1 | D38: =COUNTIF(D24:D36,"TRUE") -> 8 | E38: =COUNTIF(E24:E36,"TRUE") -> 7 | F38: =COUNTIF(F24:F36,"TRUE") -> 5 | G38: =COUNTIF(G24:G36,"TRUE") -> 6 | H38: =COUNTIF(H24:H36,"TRUE") -> 4 | I38: =COUNTIF(I24:I36,"TRUE") -> 13 | J38: =COUNTIF(J24:J36,"TRUE") -> 12 | ... AG38: =COUNTIF(AG24:AG36,"TRUE") -> 13
B39: Progress % | C39: =E41 -> 0 | D39: =D38/COUNTA(D24:D36) -> 0.61538462 | E39: =E38/COUNTA(E24:E36) -> 0.53846154 | F39: =F38/COUNTA(F24:F36) -> 0.38461538 | G39: =G38/COUNTA(G24:G36) -> 0.46153846 | H39: =H38/COUNTA(H24:H36) -> 0.30769231 | I39: =I38/COUNTA(I24:I36) -> 1 | J39: =J38/COUNTA(J24:J36) -> 0.92307692 | K39: =K38/COUNTA(K24:K36) -> 1 | ... AG39: =AG38/COUNTA(AG24:AG36) -> 1
B41: Best Habit
B42: =_xlfn.XLOOKUP(MAX(AH24:AH36),AH24:AH36,B24:B36) -> d
B44: Worst Habit
B45: =_xlfn.XLOOKUP(MIN(AH24:AH36),AH24:AH36,B24:B36) -> m

Sheet JUNE
B2: June
AD3: TOTAL PROGRESS: | AH3: 100% Complete | AI3: =COUNTIF(C39:AG39,100%) -> 21
B4: =TODAY() -> 46037 | AD4: =COUNTIF(C24:AG36,"TRUE") -> 352 | AH4: 50% Complete | AI4: =COUNTIF(C39:AG39,">50%") -> 27
B5: 2026 | AD5: =AD4/COUNTA(C24:AG36) -> 0.87344913 | AH5: 0% Complete | AI5: =COUNTIF(C39:AG39,"0%") -> 1
B7: Weekly Progress
B8: Week1
B9: =SUM(C38:I38)/COUNTA(C24:I36) -> 0.48351648
B10: Week2
B11: =SUM(J38:P38)/COUNTA(J24:P36) -> 0.98901099
B12: Week3
B13: =SUM(Q38:W38)/COUNTA(Q24:W36) -> 1
B14: Week4
B15: =SUM(X38:AD38)/COUNTA(X24:AD36) -> 0.97802198
B16: Week5
B17: =SUM(AE38:AG38)/COUNTA(AE24:AG36) -> 0.97435897
B20: Habits | C20: ="Week" &INT((DAY(C21)-1)/7)+1 -> Week1 | J20: ="Week" &INT((DAY(J21)-1)/7)+1 -> Week2 | Q20: ="Week" &INT((DAY(Q21)-1)/7)+1 -> Week3 | X20: ="Week" &INT((DAY(X21)-1)/7)+1 -> Week4 | AE20: ="Week" &INT((DAY(AE21)-1)/7)+1 -> Week5 | AH20: Complete
C21: =Sheet2!B13 -> 46174 | D21: =C21+1 -> 46175 | E21: =D21+1 -> 46176 | F21: =E21+1 -> 46177 | G21: =F21+1 -> 46178 | H21: =G21+1 -> 46179 | I21: =H21+1 -> 46180 | J21: =I21+1 -> 46181 | K21: =J21+1 -> 46182 | ... AG21: =AF21+1 -> 46204
C22: =TEXT(Sheet2!B13,"ddd") -> Mon | D22: =TEXT(D21,"ddd") -> Tue | E22: =TEXT(E21,"ddd") -> Wed | F22: =TEXT(F21,"ddd") -> Thu | G22: =TEXT(G21,"ddd") -> Fri | H22: =TEXT(H21,"ddd") -> Sat | I22: =TEXT(I21,"ddd") -> Sun | J22: =TEXT(J21,"ddd") -> Mon | K22: =TEXT(K21,"ddd") -> Tue | ... AG22: =TEXT(AG21,"ddd") -> Wed
C23: {=_xlfn.SEQUENCE(,31)} -> 1 | D23: 2 | E23: 3 | F23: 4 | G23: 5 | H23: 6 | I23: 7 | J23: 8 | K23: 9 | L23: 10 | M23: 11 | N23: 12 | O23: 13 | P23: 14 | Q23: 15 | R23: 16 | S23: 17 | T23: 18 | U23: 19 | V23: 20 | W23: 21 | X23: 22 | Y23: 23 | Z23: 24 | AA23: 25 | AB23: 26 | AC23: 27 | AD23: 28 | AE23: 29 | AF23: 30 | AG23: 31
B24: a | C24: TRUE | D24: TRUE | E24: FALSE | F24: FALSE | G24: FALSE | H24: FALSE | I24: TRUE | J24: TRUE | K24: TRUE | L24: TRUE | M24: TRUE | N24: TRUE | O24: TRUE | P24: TRUE | Q24: TRUE | R24: TRUE | S24: TRUE | T24: TRUE | U24: TRUE | V24: TRUE | W24: TRUE | X24: TRUE | Y24: TRUE | Z24: TRUE | AA24: TRUE | AB24: TRUE | AC24: TRUE | AD24: TRUE | AE24: TRUE | AF24: TRUE | AG24: TRUE | AH24: =COUNTIF(C24:AG24,"True") -> 27 | AI24: 27
B25: b | C25: FALSE | D25: FALSE | E25: TRUE | F25: TRUE | G25: FALSE | H25: FALSE | I25: TRUE | J25: TRUE | K25: TRUE | L25: TRUE | M25: TRUE | N25: TRUE | O25: TRUE | P25: TRUE | Q25: TRUE | R25: TRUE | S25: TRUE | T25: TRUE | U25: TRUE | V25: TRUE | W25: TRUE | X25: TRUE | Y25: TRUE | Z25: TRUE | AA25: TRUE | AB25: TRUE | AC25: TRUE | AD25: TRUE | AE25: TRUE | AF25: TRUE | AG25: TRUE | AH25: =COUNTIF(C25:AG25,"True") -> 27 | AI25: =COUNTIF(D25:AH25,"True") -> 27
B26: c | C26: FALSE | D26: TRUE | E26: FALSE | F26: TRUE | G26: FALSE | H26: FALSE | I26: TRUE | J26: FALSE | K26: TRUE | L26: TRUE | M26: TRUE | N26: TRUE | O26: TRUE | P26: TRUE | Q26: TRUE | R26: TRUE | S26: TRUE | T26: TRUE | U26: TRUE | V26: TRUE | W26: TRUE | X26: TRUE | Y26: TRUE | Z26: TRUE | AA26: TRUE | AB26: TRUE | AC26: TRUE | AD26: TRUE | AE26: TRUE | AF26: TRUE | AG26: TRUE | AH26: =COUNTIF(C26:AG26,"True") -> 26 | AI26: =COUNTIF(D26:AH26,"True") -> 26
B27: d | C27: FALSE | D27: TRUE | E27: TRUE | F27: TRUE | G27: TRUE | H27: TRUE | I27: TRUE | J27: TRUE | K27: TRUE | L27: TRUE | M27: TRUE | N27: TRUE | O27: TRUE | P27: TRUE | Q27: TRUE | R27: TRUE | S27: TRUE | T27: TRUE | U27: TRUE | V27: TRUE | W27: TRUE | X27: TRUE | Y27: TRUE | Z27: TRUE | AA27: TRUE | AB27: TRUE | AC27: TRUE | AD27: TRUE | AE27: TRUE | AF27: TRUE | AG27: TRUE | AH27: =COUNTIF(C27:AG27,"True") -> 30 | AI27: =COUNTIF(D27:AH27,"True") -> 30
B28: e | C28: FALSE | D28: TRUE | E28: FALSE | F28: TRUE | G28: TRUE | H28: FALSE | I28: TRUE | J28: TRUE | K28: TRUE | L28: TRUE | M28: TRUE | N28: TRUE | O28: TRUE | P28: TRUE | Q28: TRUE | R28: TRUE | S28: TRUE | T28: TRUE | U28: TRUE | V28: TRUE | W28: TRUE | X28: TRUE | Y28: TRUE | Z28: TRUE | AA28: TRUE | AB28: TRUE | AC28: TRUE | AD28: TRUE | AE28: TRUE | AF28: TRUE | AG28: TRUE | AH28: =COUNTIF(C28:AG28,"True") -> 28 | AI28: =COUNTIF(D28:AH28,"True") -> 28
B29: f | C29: FALSE | D29: TRUE | E29: TRUE | F29: FALSE | G29: FALSE | H29: TRUE | I29: TRUE | J29: TRUE | K29: TRUE | L29: TRUE | M29: TRUE | N29: TRUE | O29: TRUE | P29: TRUE | Q29: TRUE | R29: TRUE | S29: TRUE | T29: TRUE | U29: TRUE | V29: TRUE | W29: TRUE | X29: TRUE | Y29: FALSE | Z29: TRUE | AA29: TRUE | AB29: TRUE | AC29: TRUE | AD29: TRUE | AE29: TRUE | AF29: TRUE | AG29: TRUE | AH29: =COUNTIF(C29:AG29,"True") -> 27 | AI29: =COUNTIF(D29:AH29,"True") -> 27
B30: g | C30: FALSE | D30: TRUE | E30: FALSE | F30: FALSE | G30: TRUE | H30: FALSE | I30: TRUE | J30: TRUE | K30: TRUE | L30: TRUE | M30: TRUE | N30: TRUE | O30: TRUE | P30: TRUE | Q30: TRUE | R30: TRUE | S30: TRUE | T30: TRUE | U30: TRUE | V30: TRUE | W30: TRUE | X30: TRUE | Y30: TRUE | Z30: TRUE | AA30: TRUE | AB30: TRUE | AC30: TRUE | AD30: TRUE | AE30: TRUE | AF30: TRUE | AG30: TRUE | AH30: =COUNTIF(C30:AG30,"True") -> 27 | AI30: =COUNTIF(D30:AH30,"True") -> 27
B31: hh | C31: FALSE | D31: TRUE | E31: TRUE | F31: TRUE | G31: FALSE | H31: TRUE | I31: TRUE | J31: TRUE | K31: TRUE | L31: TRUE | M31: TRUE | N31: TRUE | O31: TRUE | P31: TRUE | Q31: TRUE | R31: TRUE | S31: TRUE | T31: TRUE | U31: TRUE | V31: TRUE | W31: TRUE | X31: TRUE | Y31: TRUE | Z31: TRUE | AA31: FALSE | AB31: TRUE | AC31: TRUE | AD31: TRUE | AE31: TRUE | AF31: FALSE | AG31: TRUE | AH31: =COUNTIF(C31:AG31,"True") -> 27 | AI31: =COUNTIF(D31:AH31,"True") -> 27
B32: i | C32: FALSE | D32: TRUE | E32: TRUE | F32: FALSE | G32: TRUE | H32: FALSE | I32: TRUE | J32: TRUE | K32: TRUE | L32: TRUE | M32: TRUE | N32: TRUE | O32: TRUE | P32: TRUE | Q32: TRUE | R32: TRUE | S32: TRUE | T32: TRUE | U32: TRUE | V32: TRUE | W32: TRUE | X32: TRUE | Y32: TRUE | Z32: TRUE | AA32: TRUE | AB32: TRUE | AC32: TRUE | AD32: TRUE | AE32: TRUE | AF32: TRUE | AG32: TRUE | AH32: =COUNTIF(C32:AG32,"True") -> 28 | AI32: =COUNTIF(D32:AH32,"True") -> 28
B33: j | C33: FALSE | D33: FALSE | E33: TRUE | F33: FALSE | G33: FALSE | H33: TRUE | I33: TRUE | J33: TRUE | K33: TRUE | L33: TRUE | M33: TRUE | N33: TRUE | O33: TRUE | P33: TRUE | Q33: TRUE | R33: TRUE | S33: TRUE | T33: TRUE | U33: TRUE | V33: TRUE | W33: TRUE | X33: TRUE | Y33: TRUE | Z33: TRUE | AA33: TRUE | AB33: TRUE | AC33: TRUE | AD33: TRUE | AE33: TRUE | AF33: TRUE | AG33: TRUE | AH33: =COUNTIF(C33:AG33,"True") -> 27 | AI33: =COUNTIF(D33:AH33,"True") -> 27
B34: k | C34: FALSE | D34: FALSE | E34: TRUE | F34: FALSE | G34: TRUE | H34: FALSE | I34: TRUE | J34: TRUE | K34: TRUE | L34: TRUE | M34: TRUE | N34: TRUE | O34: TRUE | P34: TRUE | Q34: TRUE | R34: TRUE | S34: TRUE | T34: TRUE | U34: TRUE | V34: TRUE | W34: TRUE | X34: TRUE | Y34: TRUE | Z34: TRUE | AA34: TRUE | AB34: TRUE | AC34: TRUE | AD34: TRUE | AE34: TRUE | AF34: TRUE | AG34: TRUE | AH34: =COUNTIF(C34:AG34,"True") -> 27 | AI34: =COUNTIF(D34:AH34,"True") -> 27
B35: l | C35: FALSE | D35: FALSE | E35: FALSE | F35: FALSE | G35: TRUE | H35: FALSE | I35: TRUE | J35: TRUE | K35: TRUE | L35: TRUE | M35: TRUE | N35: TRUE | O35: TRUE | P35: TRUE | Q35: TRUE | R35: TRUE | S35: TRUE | T35: TRUE | U35: TRUE | V35: TRUE | W35: TRUE | X35: TRUE | Y35: TRUE | Z35: TRUE | AA35: TRUE | AB35: TRUE | AC35: TRUE | AD35: TRUE | AE35: TRUE | AF35: TRUE | AG35: TRUE | AH35: =COUNTIF(C35:AG35,"True") -> 26 | AI35: =COUNTIF(D35:AH35,"True") -> 26
B36: m | C36: FALSE | D36: FALSE | E36: FALSE | F36: FALSE | G36: FALSE | H36: FALSE | I36: TRUE | J36: TRUE | K36: TRUE | L36: TRUE | M36: TRUE | N36: TRUE | O36: TRUE | P36: TRUE | Q36: TRUE | R36: TRUE | S36: TRUE | T36: TRUE | U36: TRUE | V36: TRUE | W36: TRUE | X36: TRUE | Y36: TRUE | Z36: TRUE | AA36: TRUE | AB36: TRUE | AC36: TRUE | AD36: TRUE | AE36: TRUE | AF36: TRUE | AG36: TRUE | AH36: =COUNTIF(C36:AG36,"True") -> 25 | AI36: =COUNTIF(D36:AH36,"True") -> 25
B38: Task Complete | C38: =COUNTIF(C24:C36,"TRUE") -> 1 | D38: =COUNTIF(D24:D36,"TRUE") -> 8 | E38: =COUNTIF(E24:E36,"TRUE") -> 7 | F38: =COUNTIF(F24:F36,"TRUE") -> 5 | G38: =COUNTIF(G24:G36,"TRUE") -> 6 | H38: =COUNTIF(H24:H36,"TRUE") -> 4 | I38: =COUNTIF(I24:I36,"TRUE") -> 13 | J38: =COUNTIF(J24:J36,"TRUE") -> 12 | ... AG38: =COUNTIF(AG24:AG36,"TRUE") -> 13
B39: Progress % | C39: =E41 -> 0 | D39: =D38/COUNTA(D24:D36) -> 0.61538462 | E39: =E38/COUNTA(E24:E36) -> 0.53846154 | F39: =F38/COUNTA(F24:F36) -> 0.38461538 | G39: =G38/COUNTA(G24:G36) -> 0.46153846 | H39: =H38/COUNTA(H24:H36) -> 0.30769231 | I39: =I38/COUNTA(I24:I36) -> 1 | J39: =J38/COUNTA(J24:J36) -> 0.92307692 | K39: =K38/COUNTA(K24:K36) -> 1 | ... AG39: =AG38/COUNTA(AG24:AG36) -> 1
B41: Best Habit
B42: =_xlfn.XLOOKUP(MAX(AH24:AH36),AH24:AH36,B24:B36) -> d
B44: Worst Habit
B45: =_xlfn.XLOOKUP(MIN(AH24:AH36),AH24:AH36,B24:B36) -> m

Sheet JULY
B2: July
AD3: TOTAL PROGRESS: | AH3: 100% Complete | AI3: =COUNTIF(C39:AG39,100%) -> 21
B4: =TODAY() -> 46037 | AD4: =COUNTIF(C24:AG36,"TRUE") -> 352 | AH4: 50% Complete | AI4: =COUNTIF(C39:AG39,">50%") -> 27
B5: 2026 | AD5: =AD4/COUNTA(C24:AG36) -> 0.87344913 | AH5: 0% Complete | AI5: =COUNTIF(C39:AG39,"0%") -> 1
B7: Weekly Progress
B8: Week1
B9: =SUM(C38:I38)/COUNTA(C24:I36) -> 0.48351648
B10: Week2
B11: =SUM(J38:P38)/COUNTA(J24:P36) -> 0.98901099
B12: Week3
B13: =SUM(Q38:W38)/COUNTA(Q24:W36) -> 1
B14: Week4
B15: =SUM(X38:AD38)/COUNTA(X24:AD36) -> 0.97802198
B16: Week5
B17: =SUM(AE38:AG38)/COUNTA(AE24:AG36) -> 0.97435897
B20: Habits | C20: ="Week" &INT((DAY(C21)-1)/7)+1 -> Week1 | J20: ="Week" &INT((DAY(J21)-1)/7)+1 -> Week2 | Q20: ="Week" &INT((DAY(Q21)-1)/7)+1 -> Week3 | X20: ="Week" &INT((DAY(X21)-1)/7)+1 -> Week4 | AE20: ="Week" &INT((DAY(AE21)-1)/7)+1 -> Week5 | AH20: Complete
C21: =Sheet2!B8 -> 46204 | D21: =C21+1 -> 46205 | E21: =D21+1 -> 46206 | F21: =E21+1 -> 46207 | G21: =F21+1 -> 46208 | H21: =G21+1 -> 46209 | I21: =H21+1 -> 46210 | J21: =I21+1 -> 46211 | K21: =J21+1 -> 46212 | ... AG21: =AF21+1 -> 46234
C22: =TEXT(Sheet2!B8,"ddd") -> Wed | D22: =TEXT(D21,"ddd") -> Thu | E22: =TEXT(E21,"ddd") -> Fri | F22: =TEXT(F21,"ddd") -> Sat | G22: =TEXT(G21,"ddd") -> Sun | H22: =TEXT(H21,"ddd") -> Mon | I22: =TEXT(I21,"ddd") -> Tue | J22: =TEXT(J21,"ddd") -> Wed | K22: =TEXT(K21,"ddd") -> Thu | ... AG22: =TEXT(AG21,"ddd") -> Fri
C23: {=_xlfn.SEQUENCE(,31)} -> 1 | D23: 2 | E23: 3 | F23: 4 | G23: 5 | H23: 6 | I23: 7 | J23: 8 | K23: 9 | L23: 10 | M23: 11 | N23: 12 | O23: 13 | P23: 14 | Q23: 15 | R23: 16 | S23: 17 | T23: 18 | U23: 19 | V23: 20 | W23: 21 | X23: 22 | Y23: 23 | Z23: 24 | AA23: 25 | AB23: 26 | AC23: 27 | AD23: 28 | AE23: 29 | AF23: 30 | AG23: 31
B24: a | C24: TRUE | D24: TRUE | E24: FALSE | F24: FALSE | G24: FALSE | H24: FALSE | I24: TRUE | J24: TRUE | K24: TRUE | L24: TRUE | M24: TRUE | N24: TRUE | O24: TRUE | P24: TRUE | Q24: TRUE | R24: TRUE | S24: TRUE | T24: TRUE | U24: TRUE | V24: TRUE | W24: TRUE | X24: TRUE | Y24: TRUE | Z24: TRUE | AA24: TRUE | AB24: TRUE | AC24: TRUE | AD24: TRUE | AE24: TRUE | AF24: TRUE | AG24: TRUE | AH24: =COUNTIF(C24:AG24,"True") -> 27 | AI24: 27
B25: b | C25: FALSE | D25: FALSE | E25: TRUE | F25: TRUE | G25: FALSE | H25: FALSE | I25: TRUE | J25: TRUE | K25: TRUE | L25: TRUE | M25: TRUE | N25: TRUE | O25: TRUE | P25: TRUE | Q25: TRUE | R25: TRUE | S25: TRUE | T25: TRUE | U25: TRUE | V25: TRUE | W25: TRUE | X25: TRUE | Y25: TRUE | Z25: TRUE | AA25: TRUE | AB25: TRUE | AC25: TRUE | AD25: TRUE | AE25: TRUE | AF25: TRUE | AG25: TRUE | AH25: =COUNTIF(C25:AG25,"True") -> 27 | AI25: =COUNTIF(D25:AH25,"True") -> 27
B26: c | C26: FALSE | D26: TRUE | E26: FALSE | F26: TRUE | G26: FALSE | H26: FALSE | I26: TRUE | J26: FALSE | K26: TRUE | L26: TRUE | M26: TRUE | N26: TRUE | O26: TRUE | P26: TRUE | Q26: TRUE | R26: TRUE | S26: TRUE | T26: TRUE | U26: TRUE | V26: TRUE | W26: TRUE | X26: TRUE | Y26: TRUE | Z26: TRUE | AA26: TRUE | AB26: TRUE | AC26: TRUE | AD26: TRUE | AE26: TRUE | AF26: TRUE | AG26: TRUE | AH26: =COUNTIF(C26:AG26,"True") -> 26 | AI26: =COUNTIF(D26:AH26,"True") -> 26
B27: d | C27: FALSE | D27: TRUE | E27: TRUE | F27: TRUE | G27: TRUE | H27: TRUE | I27: TRUE | J27: TRUE | K27: TRUE | L27: TRUE | M27: TRUE | N27: TRUE | O27: TRUE | P27: TRUE | Q27: TRUE | R27: TRUE | S27: TRUE | T27: TRUE | U27: TRUE | V27: TRUE | W27: TRUE | X27: TRUE | Y27: TRUE | Z27: TRUE | AA27: TRUE | AB27: TRUE | AC27: TRUE | AD27: TRUE | AE27: TRUE | AF27: TRUE | AG27: TRUE | AH27: =COUNTIF(C27:AG27,"True") -> 30 | AI27: =COUNTIF(D27:AH27,"True") -> 30
B28: e | C28: FALSE | D28: TRUE | E28: FALSE | F28: TRUE | G28: TRUE | H28: FALSE | I28: TRUE | J28: TRUE | K28: TRUE | L28: TRUE | M28: TRUE | N28: TRUE | O28: TRUE | P28: TRUE | Q28: TRUE | R28: TRUE | S28: TRUE | T28: TRUE | U28: TRUE | V28: TRUE | W28: TRUE | X28: TRUE | Y28: TRUE | Z28: TRUE | AA28: TRUE | AB28: TRUE | AC28: TRUE | AD28: TRUE | AE28: TRUE | AF28: TRUE | AG28: TRUE | AH28: =COUNTIF(C28:AG28,"True") -> 28 | AI28: =COUNTIF(D28:AH28,"True") -> 28
B29: f | C29: FALSE | D29: TRUE | E29: TRUE | F29: FALSE | G29: FALSE | H29: TRUE | I29: TRUE | J29: TRUE | K29: TRUE | L29: TRUE | M29: TRUE | N29: TRUE | O29: TRUE | P29: TRUE | Q29: TRUE | R29: TRUE | S29: TRUE | T29: TRUE | U29: TRUE | V29: TRUE | W29: TRUE | X29: TRUE | Y29: FALSE | Z29: TRUE | AA29: TRUE | AB29: TRUE | AC29: TRUE | AD29: TRUE | AE29: TRUE | AF29: TRUE | AG29: TRUE | AH29: =COUNTIF(C29:AG29,"True") -> 27 | AI29: =COUNTIF(D29:AH29,"True") -> 27
B30: g | C30: FALSE | D30: TRUE | E30: FALSE | F30: FALSE | G30: TRUE | H30: FALSE | I30: TRUE | J30: TRUE | K30: TRUE | L30: TRUE | M30: TRUE | N30: TRUE | O30: TRUE | P30: TRUE | Q30: TRUE | R30: TRUE | S30: TRUE | T30: TRUE | U30: TRUE | V30: TRUE | W30: TRUE | X30: TRUE | Y30: TRUE | Z30: TRUE | AA30: TRUE | AB30: TRUE | AC30: TRUE | AD30: TRUE | AE30: TRUE | AF30: TRUE | AG30: TRUE | AH30: =COUNTIF(C30:AG30,"True") -> 27 | AI30: =COUNTIF(D30:AH30,"True") -> 27
B31: hh | C31: FALSE | D31: TRUE | E31: TRUE | F31: TRUE | G31: FALSE | H31: TRUE | I31: TRUE | J31: TRUE | K31: TRUE | L31: TRUE | M31: TRUE | N31: TRUE | O31: TRUE | P31: TRUE | Q31: TRUE | R31: TRUE | S31: TRUE | T31: TRUE | U31: TRUE | V31: TRUE | W31: TRUE | X31: TRUE | Y31: TRUE | Z31: TRUE | AA31: FALSE | AB31: TRUE | AC31: TRUE | AD31: TRUE | AE31: TRUE | AF31: FALSE | AG31: TRUE | AH31: =COUNTIF(C31:AG31,"True") -> 27 | AI31: =COUNTIF(D31:AH31,"True") -> 27
B32: i | C32: FALSE | D32: TRUE | E32: TRUE | F32: FALSE | G32: TRUE | H32: FALSE | I32: TRUE | J32: TRUE | K32: TRUE | L32: TRUE | M32: TRUE | N32: TRUE | O32: TRUE | P32: TRUE | Q32: TRUE | R32: TRUE | S32: TRUE | T32: TRUE | U32: TRUE | V32: TRUE | W32: TRUE | X32: TRUE | Y32: TRUE | Z32: TRUE | AA32: TRUE | AB32: TRUE | AC32: TRUE | AD32: TRUE | AE32: TRUE | AF32: TRUE | AG32: TRUE | AH32: =COUNTIF(C32:AG32,"True") -> 28 | AI32: =COUNTIF(D32:AH32,"True") -> 28
B33: j | C33: FALSE | D33: FALSE | E33: TRUE | F33: FALSE | G33: FALSE | H33: TRUE | I33: TRUE | J33: TRUE | K33: TRUE | L33: TRUE | M33: TRUE | N33: TRUE | O33: TRUE | P33: TRUE | Q33: TRUE | R33: TRUE | S33: TRUE | T33: TRUE | U33: TRUE | V33: TRUE | W33: TRUE | X33: TRUE | Y33: TRUE | Z33: TRUE | AA33: TRUE | AB33: TRUE | AC33: TRUE | AD33: TRUE | AE33: TRUE | AF33: TRUE | AG33: TRUE | AH33: =COUNTIF(C33:AG33,"True") -> 27 | AI33: =COUNTIF(D33:AH33,"True") -> 27
